Workbook

Sheet Sheet1
A1: Region | B1: Property_Type | C1: Average_Price | D1: Sales_Volume | E1: Year | F1: Mortgage_Rate | G1: Deposit_Percent | H1: Energy_Rating | I1: New_Build | J1: Buyer_Type
A2: London | B2: Detached | C2: 785000 | D2: 1200 | E2: 2023 | F2: 6.1 | G2: 18 | H2: B | I2: Yes | J2: Investor
A3: South East | B3: Flat | C3: 298000 | D3: 1200 | E3: 2024 | F3: 5.4 | G3: 12 | H3: C | I3: No | J3: First Timer
A4: North West | B4: Terraced | C4: 252000 | D4: 1990 | E4: 2023 | F4: 6.3 | G4: 10 | H4: D | I4: No | J4: First Timer
A5: Yorkshire | B5: Semi Detached | C5: 305000 | D5: 1840 | E5: 2024 | F5: 5.2 | G5: 15 | H5: C | I5: No | J5: Upsizer
A6: East Midlands | B6: Flat | C6: 218000 | D6: 740 | E6: 2023 | F6: 6.5 | G6: 8 | H6: D | I6: No | J6: First Timer
A7: West Midlands | B7: Detached | C7: 435000 | D7: 1320 | E7: 2024 | F7: 5.1 | G7: 10 | H7: B | I7: Yes | J7: Investor
A8: South West | B8: Terraced | C8: 318000 | D8: 1760 | E8: 2023 | F8: 6.4 | G8: 21 | H8: C | I8: No | J8: First Timer
A9: North East | B9: Flat | C9: 168000 | D9: 1880 | E9: 2024 | F9: 5.3 | G9: 5 | H9: D | I9: No | J9: First Timer
A10: East of England | B10: Detached | C10: 512000 | D10: 1490 | E10: 2023 | F10: 6.2 | G10: 22 | H10: B | I10: Yes | J10: Upsizer
A11: London | B11: Flat | C11: 438000 | D11: 2600 | E11: 2024 | F11: 5 | G11: 12 | H11: C | I11: No | J11: First Timer
A12: South East | B12: Semi Detached | C12: 428000 | D12: 2050 | E12: 2024 | F12: 5.3 | G12: 15 | H12: B | I12: No | J12: Upsizer
A13: North West | B13: Detached | C13: 392000 | D13: 1410 | E13: 2023 | F13: 6.4 | G13: 18 | H13: C | I13: Yes | J13: Investor
A14: Yorkshire | B14: Terraced | C14: 240000 | D14: 2140 | E14: 2024 | F14: 5.5 | G14: 10 | H14: D | I14: No | J14: First Timer
A15: East Midlands | B15: Semi Detached | C15: 322000 | D15: 1580 | E15: 2024 | F15: 5.4 | G15: 14 | H15: C | I15: No | J15: Upsizer
A16: West Midlands | B16: Flat | C16: 228000 | D16: 2100 | E16: 2023 | F16: 6.6 | G16: 7 | H16: D | I16: No | J16: First Timer
A17: South West | B17: Detached | C17: 480000 | D17: 1300 | E17: 2024 | F17: 5.2 | G17: 20 | H17: B | I17: Yes | J17: Investor
A18: North East | B18: Terraced | C18: 212000 | D18: 1820 | E18: 2023 | F18: 6.7 | G18: 6 | H18: D | I18: No | J18: First Timer
A19: East of England | B19: Flat | C19: 273000 | D19: 2430 | E19: 2024 | F19: 5.1 | G19: 10 | H19: C | I19: No | J19: First Timer
... A97: West Midlands | B97: Detached | C97: 445000 | D97: 1400 | E97: 2023 | F97: 6.1 | G97: 20 | H97: B | I97: Yes | J97: Investor
A98: South West | B98: Terraced | C98: 330000 | D98: 2050 | E98: 2024 | F98: 5.3 | G98: 10 | H98: C | I98: No | J98: First Timer
A99: North East | B99: Flat | C99: 175000 | D99: 2200 | E99: 2023 | F99: 6.4 | G99: 5 | H99: D | I99: No | J99: First Timer
A100: East of England | B100: Detached | C100: 525000 | D100: 1530 | E100: 2024 | F100: 5.1 | G100: 22 | H100: B | I100: Yes | J100: Upsizer
A101: London | B101: Flat | C101: 450000 | D101: 2680 | E101: 2024 | F101: 5 | G101: 12 | H101: C | I101: No | J101: First Timer
A102: South East | B102: Semi Detached | C102: 432000 | D102: 2120 | E102: 2023 | F102: 6.1 | G102: 15 | H102: B | I102: No | J102: Upsizer
A103: North West | B103: Detached | C103: 398000 | D103: 1460 | E103: 2024 | F103: 5.3 | G103: 18 | H103: C | I103: Yes | J103: Investor
A104: Yorkshire | B104: Terraced | C104: 248000 | D104: 2200 | E104: 2023 | F104: 6.5 | G104: 10 | H104: D | I104: No | J104: First Timer
A105: East Midlands | B105: Semi Detached | C105: 330000 | D105: 1620 | E105: 2024 | F105: 5.4 | G105: 14 | H105: C | I105: No | J105: Upsizer
A106: West Midlands | B106: Flat | C106: 232000 | D106: 2230 | E106: 2024 | F106: 5.3 | G106: 7 | H106: D | I106: No | J106: First Timer
A107: South West | B107: Detached | C107: 495000 | D107: 1450 | E107: 2023 | F107: 6.2 | G107: 20 | H107: B | I107: Yes | J107: Investor
A108: North East | B108: Terraced | C108: 218000 | D108: 1880 | E108: 2024 | F108: 5.3 | G108: 6 | H108: D | I108: No | J108: First Timer
A109: East of England | B109: Flat | C109: 282000 | D109: 2510 | E109: 2024 | F109: 5.2 | G109: 10 | H109: C | I109: No | J109: First Timer
A110: London | B110: Terraced | C110: 560000 | D110: 2300 | E110: 2024 | F110: 5.1 | G110: 15 | H110: B | I110: No | J110: Upsizer
... A187: West Midlands | B187: Detached | C187: 460000 | D187: 1420 | E187: 2023 | F187: 6.1 | G187: 20 | H187: B | I187: Yes | J187: Investor
A188: South West | B188: Terraced | C188: 345000 | D188: 2120 | E188: 2024 | F188: 5.3 | G188: 10 | H188: C | I188: No | J188: First Timer
A189: North East | B189: Flat | C189: 185000 | D189: 2200 | E189: 2023 | F189: 6.4 | G189: 5 | H189: D | I189: No | J189: First Timer
A190: East of England | B190: Detached | C190: 545000 | D190: 1620 | E190: 2024 | F190: 5.2 | G190: 22 | H190: B | I190: Yes | J190: Upsizer
A191: London | B191: Flat | C191: 460000 | D191: 2750 | E191: 2024 | F191: 5 | G191: 12 | H191: C | I191: No | J191: First Timer
A192: South East | B192: Semi Detached | C192: 450000 | D192: 2200 | E192: 2024 | F192: 5.3 | G192: 15 | H192: B | I192: No | J192: Upsizer
A193: North West | B193: Detached | C193: 405000 | D193: 1500 | E193: 2023 | F193: 6.3 | G193: 18 | H193: C | I193: Yes | J193: Investor
...

Sheet Copy
A1: Region | B1: Property_Type | C1: Average_Price | D1: Sales_Volume | E1: Year | F1: Mortgage_Rate | G1: Deposit_Percent | H1: Energy_Rating | I1: New_Build | J1: Buyer_Type | K1: Affordability_Index | L1: Monthly_Mortgage_cost | M1: Total Interest Paid | N1: 25-Year total cost | O1: Loan Amount | P1: Investment_Score | S1: Investment_Score_1
A2: North East | B2: Flat | C2: 175000 | D2: 2200 | E2: 2023 | F2: 6.4 | G2: 5 | H2: D | I2: No | J2: First Timer | K2: =C2/D2 -> 79.545455 | L2: =PMT(F2/100/12, 300, -(C2 * (1 - G2/100))) -> 1112.1657 | M2: =-CUMIPMT(F2/1200,300,O2,1,300,0) -> 167399.72 | N2: =O2+M2 -> 333649.72 | O2: =C2*(1-G2/100) -> 166250 | P2: 880.30377 | R2: =IF(H2="A","4",IF(H2="B","3",IF(H2="C","2",IF(H2="D","1",0)))) -> 1 | S2: =D2*0.4 +R2*0.3 +(1/(K2*0.3)) -> 880.3419
A3: Yorkshire | B3: Flat | C3: 190000 | D3: 2380 | E3: 2024 | F3: 5.5 | G3: 5 | H3: D | I3: No | J3: First Timer | K3: =C3/D3 -> 79.831933 | L3: =PMT(F3/100/12, 300, -(C3 * (1 - G3/100))) -> 1108.4279 | M3: =-CUMIPMT(F3/1200,300,O3,1,300,0) -> 152028.38 | N3: =O3+M3 -> 332528.38 | O3: =C3*(1-G3/100) -> 180500 | P3: 952.30376 | R3: =IF(H3="A","4",IF(H3="B","3",IF(H3="C","2",IF(H3="D","1",0)))) -> 1 | S3: =D3*0.4 +R3*0.3 +(1/(K3*0.3)) -> 952.34175
A4: North East | B4: Flat | C4: 225000 | D4: 2800 | E4: 2024 | F4: 5.4 | G4: 8 | H4: D | I4: No | J4: First Timer | K4: =C4/D4 -> 80.357143 | L4: =PMT(F4/100/12, 300, -(C4 * (1 - G4/100))) -> 1258.8289 | M4: =-CUMIPMT(F4/1200,300,O4,1,300,0) -> 170648.68 | N4: =O4+M4 -> 377648.68 | O4: =C4*(1-G4/100) -> 207000 | P4: 1120.3037 | R4: =IF(H4="A","4",IF(H4="B","3",IF(H4="C","2",IF(H4="D","1",0)))) -> 1 | S4: =D4*0.4 +R4*0.3 +(1/(K4*0.3)) -> 1120.3415
A5: North East | B5: Flat | C5: 230000 | D5: 2850 | E5: 2024 | F5: 5.4 | G5: 8 | H5: D | I5: No | J5: First Timer | K5: =C5/D5 -> 80.701754 | L5: =PMT(F5/100/12, 300, -(C5 * (1 - G5/100))) -> 1286.8029 | M5: =-CUMIPMT(F5/1200,300,O5,1,300,0) -> 174440.87 | N5: =O5+M5 -> 386040.87 | O5: =C5*(1-G5/100) -> 211600 | P5: 1140.3037 | R5: =IF(H5="A","4",IF(H5="B","3",IF(H5="C","2",IF(H5="D","1",0)))) -> 1 | S5: =D5*0.4 +R5*0.3 +(1/(K5*0.3)) -> 1140.3413
A6: Yorkshire | B6: Flat | C6: 194000 | D6: 2400 | E6: 2024 | F6: 5.4 | G6: 5 | H6: D | I6: No | J6: First Timer | K6: =C6/D6 -> 80.833333 | L6: =PMT(F6/100/12, 300, -(C6 * (1 - G6/100))) -> 1120.7834 | M6: =-CUMIPMT(F6/1200,300,O6,1,300,0) -> 151935.03 | N6: =O6+M6 -> 336235.03 | O6: =C6*(1-G6/100) -> 184300 | P6: 960.30371 | R6: =IF(H6="A","4",IF(H6="B","3",IF(H6="C","2",IF(H6="D","1",0)))) -> 1 | S6: =D6*0.4 +R6*0.3 +(1/(K6*0.3)) -> 960.34124
A7: North East | B7: Flat | C7: 235000 | D7: 2900 | E7: 2024 | F7: 5.4 | G7: 8 | H7: D | I7: No | J7: First Timer | K7: =C7/D7 -> 81.034483 | L7: =PMT(F7/100/12, 300, -(C7 * (1 - G7/100))) -> 1314.7769 | M7: =-CUMIPMT(F7/1200,300,O7,1,300,0) -> 178233.06 | N7: =O7+M7 -> 394433.06 | O7: =C7*(1-G7/100) -> 216200 | P7: 1160.3037 | R7: =IF(H7="A","4",IF(H7="B","3",IF(H7="C","2",IF(H7="D","1",0)))) -> 1 | S7: =D7*0.4 +R7*0.3 +(1/(K7*0.3)) -> 1160.3411
A8: North East | B8: Flat | C8: 236000 | D8: 2910 | E8: 2024 | F8: 5.4 | G8: 8 | H8: D | I8: No | J8: First Timer | K8: =C8/D8 -> 81.099656 | L8: =PMT(F8/100/12, 300, -(C8 * (1 - G8/100))) -> 1320.3717 | M8: =-CUMIPMT(F8/1200,300,O8,1,300,0) -> 178991.5 | N8: =O8+M8 -> 396111.5 | O8: =C8*(1-G8/100) -> 217120 | P8: 1164.3037 | R8: =IF(H8="A","4",IF(H8="B","3",IF(H8="C","2",IF(H8="D","1",0)))) -> 1 | S8: =D8*0.4 +R8*0.3 +(1/(K8*0.3)) -> 1164.3411
A9: North East | B9: Flat | C9: 220000 | D9: 2700 | E9: 2024 | F9: 5.4 | G9: 8 | H9: D | I9: No | J9: First Timer | K9: =C9/D9 -> 81.481481 | L9: =PMT(F9/100/12, 300, -(C9 * (1 - G9/100))) -> 1230.855 | M9: =-CUMIPMT(F9/1200,300,O9,1,300,0) -> 166856.49 | N9: =O9+M9 -> 369256.49 | O9: =C9*(1-G9/100) -> 202400 | P9: 1080.3037 | R9: =IF(H9="A","4",IF(H9="B","3",IF(H9="C","2",IF(H9="D","1",0)))) -> 1 | S9: =D9*0.4 +R9*0.3 +(1/(K9*0.3)) -> 1080.3409
A10: Yorkshire | B10: Flat | C10: 200000 | D10: 2450 | E10: 2024 | F10: 5.4 | G10: 5 | H10: D | I10: No | J10: First Timer | K10: =C10/D10 -> 81.632653 | L10: =PMT(F10/100/12, 300, -(C10 * (1 - G10/100))) -> 1155.4468 | M10: =-CUMIPMT(F10/1200,300,O10,1,300,0) -> 156634.05 | N10: =O10+M10 -> 346634.05 | O10: =C10*(1-G10/100) -> 190000 | P10: 980.30367 | R10: =IF(H10="A","4",IF(H10="B","3",IF(H10="C","2",IF(H10="D","1",0)))) -> 1 | S10: =D10*0.4 +R10*0.3 +(1/(K10*0.3)) -> 980.34083
A11: Yorkshire | B11: Flat | C11: 198000 | D11: 2420 | E11: 2023 | F11: 6.6 | G11: 5 | H11: D | I11: No | J11: First Timer | K11: =C11/D11 -> 81.818182 | L11: =PMT(F11/100/12, 300, -(C11 * (1 - G11/100))) -> 1281.8434 | M11: =-CUMIPMT(F11/1200,300,O11,1,300,0) -> 196453.01 | N11: =O11+M11 -> 384553.01 | O11: =C11*(1-G11/100) -> 188100 | P11: 968.30367 | R11: =IF(H11="A","4",IF(H11="B","3",IF(H11="C","2",IF(H11="D","1",0)))) -> 1 | S11: =D11*0.4 +R11*0.3 +(1/(K11*0.3)) -> 968.34074
A12: North East | B12: Flat | C12: 180000 | D12: 2200 | E12: 2023 | F12: 6.4 | G12: 5 | H12: D | I12: No | J12: First Timer | K12: =C12/D12 -> 81.818182 | L12: =PMT(F12/100/12, 300, -(C12 * (1 - G12/100))) -> 1143.9419 | M12: =-CUMIPMT(F12/1200,300,O12,1,300,0) -> 172182.57 | N12: =O12+M12 -> 343182.57 | O12: =C12*(1-G12/100) -> 171000 | P12: 880.30367 | R12: =IF(H12="A","4",IF(H12="B","3",IF(H12="C","2",IF(H12="D","1",0)))) -> 1 | S12: =D12*0.4 +R12*0.3 +(1/(K12*0.3)) -> 880.34074
A13: Yorkshire | B13: Flat | C13: 188000 | D13: 2290 | E13: 2023 | F13: 6.5 | G13: 5 | H13: D | I13: No | J13: First Timer | K13: =C13/D13 -> 82.09607 | L13: =PMT(F13/100/12, 300, -(C13 * (1 - G13/100))) -> 1205.92 | M13: =-CUMIPMT(F13/1200,300,O13,1,300,0) -> 183176 | N13: =O13+M13 -> 361776 | O13: =C13*(1-G13/100) -> 178600 | P13: 916.30365 | R13: =IF(H13="A","4",IF(H13="B","3",IF(H13="C","2",IF(H13="D","1",0)))) -> 1 | S13: =D13*0.4 +R13*0.3 +(1/(K13*0.3)) -> 916.3406
... A25: North East | B25: Flat | C25: 188000 | D25: 2250 | E25: 2024 | F25: 5.4 | G25: 8 | H25: D | I25: No | J25: First Timer | K25: =C25/D25 -> 83.555556 | L25: =PMT(F25/100/12, 300, -(C25 * (1 - G25/100))) -> 1051.8215 | M25: =-CUMIPMT(F25/1200,300,O25,1,300,0) -> 142586.45 | N25: =O25+M25 -> 315546.45 | O25: =C25*(1-G25/100) -> 172960 | P25: 900.30359 | R25: =IF(H25="A","4",IF(H25="B","3",IF(H25="C","2",IF(H25="D","1",0)))) -> 1 | S25: =D25*0.4 +R25*0.3 +(1/(K25*0.3)) -> 900.33989
A26: North East | B26: Flat | C26: 180000 | D26: 2150 | E26: 2024 | F26: 5.4 | G26: 8 | H26: D | I26: No | J26: First Timer | K26: =C26/D26 -> 83.72093 | L26: =PMT(F26/100/12, 300, -(C26 * (1 - G26/100))) -> 1007.0631 | M26: =-CUMIPMT(F26/1200,300,O26,1,300,0) -> 136518.94 | N26: =O26+M26 -> 302118.94 | O26: =C26*(1-G26/100) -> 165600 | P26: 860.30358 | R26: =IF(H26="A","4",IF(H26="B","3",IF(H26="C","2",IF(H26="D","1",0)))) -> 1 | S26: =D26*0.4 +R26*0.3 +(1/(K26*0.3)) -> 860.33981
A27: North East | B27: Flat | C27: 166000 | D27: 1980 | E27: 2023 | F27: 6.4 | G27: 8 | H27: D | I27: No | J27: First Timer | K27: =C27/D27 -> 83.838384 | L27: =PMT(F27/100/12, 300, -(C27 * (1 - G27/100))) -> 1021.6539 | M27: =-CUMIPMT(F27/1200,300,O27,1,300,0) -> 153776.16 | N27: =O27+M27 -> 306496.16 | O27: =C27*(1-G27/100) -> 152720 | P27: 792.30358 | R27: =IF(H27="A","4",IF(H27="B","3",IF(H27="C","2",IF(H27="D","1",0)))) -> 1 | S27: =D27*0.4 +R27*0.3 +(1/(K27*0.3)) -> 792.33976
A28: Yorkshire | B28: Flat | C28: 210000 | D28: 2500 | E28: 2024 | F28: 5.4 | G28: 5 | H28: D | I28: No | J28: First Timer | K28: =C28/D28 -> 84 | L28: =PMT(F28/100/12, 300, -(C28 * (1 - G28/100))) -> 1213.2192 | M28: =-CUMIPMT(F28/1200,300,O28,1,300,0) -> 164465.76 | N28: =O28+M28 -> 363965.76 | O28: =C28*(1-G28/100) -> 199500 | P28: 1000.3036 | R28: =IF(H28="A","4",IF(H28="B","3",IF(H28="C","2",IF(H28="D","1",0)))) -> 1 | S28: =D28*0.4 +R28*0.3 +(1/(K28*0.3)) -> 1000.3397
A29: North East | B29: Flat | C29: 210000 | D29: 2500 | E29: 2024 | F29: 5.4 | G29: 8 | H29: D | I29: No | J29: First Timer | K29: =C29/D29 -> 84 | L29: =PMT(F29/100/12, 300, -(C29 * (1 - G29/100))) -> 1174.907 | M29: =-CUMIPMT(F29/1200,300,O29,1,300,0) -> 159272.1 | N29: =O29+M29 -> 352472.1 | O29: =C29*(1-G29/100) -> 193200 | P29: 1000.3036 | R29: =IF(H29="A","4",IF(H29="B","3",IF(H29="C","2",IF(H29="D","1",0)))) -> 1 | S29: =D29*0.4 +R29*0.3 +(1/(K29*0.3)) -> 1000.3397
A30: North East | B30: Flat | C30: 185000 | D30: 2200 | E30: 2023 | F30: 6.4 | G30: 5 | H30: D | I30: No | J30: First Timer | K30: =C30/D30 -> 84.090909 | L30: =PMT(F30/100/12, 300, -(C30 * (1 - G30/100))) -> 1175.7181 | M30: =-CUMIPMT(F30/1200,300,O30,1,300,0) -> 176965.42 | N30: =O30+M30 -> 352715.42 | O30: =C30*(1-G30/100) -> 175750 | P30: 880.30357 | R30: =IF(H30="A","4",IF(H30="B","3",IF(H30="C","2",IF(H30="D","1",0)))) -> 1 | S30: =D30*0.4 +R30*0.3 +(1/(K30*0.3)) -> 880.33964
A31: North East | B31: Flat | C31: 185000 | D31: 2200 | E31: 2024 | F31: 5.4 | G31: 8 | H31: D | I31: No | J31: First Timer | K31: =C31/D31 -> 84.090909 | L31: =PMT(F31/100/12, 300, -(C31 * (1 - G31/100))) -> 1035.0371 | M31: =-CUMIPMT(F31/1200,300,O31,1,300,0) -> 140311.14 | N31: =O31+M31 -> 310511.14 | O31: =C31*(1-G31/100) -> 170200 | P31: 880.30357 | R31: =IF(H31="A","4",IF(H31="B","3",IF(H31="C","2",IF(H31="D","1",0)))) -> 1 | S31: =D31*0.4 +R31*0.3 +(1/(K31*0.3)) -> 880.33964
A32: North East | B32: Flat | C32: 190000 | D32: 2250 | E32: 2024 | F32: 5.4 | G32: 8 | H32: D | I32: No | J32: First Timer | K32: =C32/D32 -> 84.444444 | L32: =PMT(F32/100/12, 300, -(C32 * (1 - G32/100))) -> 1063.0111 | M32: =-CUMIPMT(F32/1200,300,O32,1,300,0) -> 144103.33 | N32: =O32+M32 -> 318903.33 | O32: =C32*(1-G32/100) -> 174800 | P32: 900.30355 | R32: =IF(H32="A","4",IF(H32="B","3",IF(H32="C","2",IF(H32="D","1",0)))) -> 1 | S32: =D32*0.4 +R32*0.3 +(1/(K32*0.3)) -> 900.33947
A33: North West | B33: Flat | C33: 210000 | D33: 2480 | E33: 2024 | F33: 5.4 | G33: 5 | H33: D | I33: No | J33: First Timer | K33: =C33/D33 -> 84.677419 | L33: =PMT(F33/100/12, 300, -(C33 * (1 - G33/100))) -> 1213.2192 | M33: =-CUMIPMT(F33/1200,300,O33,1,300,0) -> 164465.76 | N33: =O33+M33 -> 363965.76 | O33: =C33*(1-G33/100) -> 199500 | P33: 992.30354 | R33: =IF(H33="A","4",IF(H33="B","3",IF(H33="C","2",IF(H33="D","1",0)))) -> 1 | S33: =D33*0.4 +R33*0.3 +(1/(K33*0.3)) -> 992.33937
A34: Yorkshire | B34: Flat | C34: 205000 | D34: 2420 | E34: 2023 | F34: 6.6 | G34: 5 | H34: D | I34: No | J34: First Timer | K34: =C34/D34 -> 84.710744 | L34: =PMT(F34/100/12, 300, -(C34 * (1 - G34/100))) -> 1327.1611 | M34: =-CUMIPMT(F34/1200,300,O34,1,300,0) -> 203398.32 | N34: =O34+M34 -> 398148.32 | O34: =C34*(1-G34/100) -> 194750 | P34: 968.30354 | R34: =IF(H34="A","4",IF(H34="B","3",IF(H34="C","2",IF(H34="D","1",0)))) -> 1 | S34: =D34*0.4 +R34*0.3 +(1/(K34*0.3)) -> 968.33935
A35: North East | B35: Flat | C35: 195000 | D35: 2300 | E35: 2023 | F35: 6.4 | G35: 8 | H35: D | I35: No | J35: First Timer | K35: =C35/D35 -> 84.782609 | L35: =PMT(F35/100/12, 300, -(C35 * (1 - G35/100))) -> 1200.1355 | M35: =-CUMIPMT(F35/1200,300,O35,1,300,0) -> 180640.66 | N35: =O35+M35 -> 360040.66 | O35: =C35*(1-G35/100) -> 179400 | P35: 920.30354 | R35: =IF(H35="A","4",IF(H35="B","3",IF(H35="C","2",IF(H35="D","1",0)))) -> 1 | S35: =D35*0.4 +R35*0.3 +(1/(K35*0.3)) -> 920.33932
A36: North East | B36: Flat | C36: 195000 | D36: 2300 | E36: 2024 | F36: 5.4 | G36: 8 | H36: D | I36: No | J36: First Timer | K36: =C36/D36 -> 84.782609 | L36: =PMT(F36/100/12, 300, -(C36 * (1 - G36/100))) -> 1090.9851 | M36: =-CUMIPMT(F36/1200,300,O36,1,300,0) -> 147895.52 | N36: =O36+M36 -> 327295.52 | O36: =C36*(1-G36/100) -> 179400 | P36: 920.30354 | R36: =IF(H36="A","4",IF(H36="B","3",IF(H36="C","2",IF(H36="D","1",0)))) -> 1 | S36: =D36*0.4 +R36*0.3 +(1/(K36*0.3)) -> 920.33932
A37: North West | B37: Flat | C37: 212000 | D37: 2500 | E37: 2023 | F37: 6.4 | G37: 5 | H37: D | I37: No | J37: First Timer | K37: =C37/D37 -> 84.8 | L37: =PMT(F37/100/12, 300, -(C37 * (1 - G37/100))) -> 1347.3094 | M37: =-CUMIPMT(F37/1200,300,O37,1,300,0) -> 202792.81 | N37: =O37+M37 -> 404192.81 | O37: =C37*(1-G37/100) -> 201400 | P37: 1000.3035 | R37: =IF(H37="A","4",IF(H37="B","3",IF(H37="C","2",IF(H37="D","1",0)))) -> 1 | S37: =D37*0.4 +R37*0.3 +(1/(K37*0.3)) -> 1000.3393
A38: North East | B38: Flat | C38: 200000 | D38: 2350 | E38: 2023 | F38: 6.4 | G38: 5 | H38: D | I38: No | J38: First Timer | K38: =C38/D38 -> 85.106383 | L38: =PMT(F38/100/12, 300, -(C38 * (1 - G38/100))) -> 1271.0466 | M38: =-CUMIPMT(F38/1200,300,O38,1,300,0) -> 191313.97 | N38: =O38+M38 -> 381313.97 | O38: =C38*(1-G38/100) -> 190000 | P38: 940.30352 | R38: =IF(H38="A","4",IF(H38="B","3",IF(H38="C","2",IF(H38="D","1",0)))) -> 1 | S38: =D38*0.4 +R38*0.3 +(1/(K38*0.3)) -> 940.33917
... A144: East of England | B144: Flat | C144: 279000 | D144: 2490 | E144: 2023 | F144: 6 | G144: 10 | H144: C | I144: No | J144: First Timer | K144: =C144/D144 -> 112.04819 | L144: =PMT(F144/100/12, 300, -(C144 * (1 - G144/100))) -> 1617.8408 | M144: =-CUMIPMT(F144/1200,300,O144,1,300,0) -> 234252.25 | N144: =O144+M144 -> 485352.25 | O144: =C144*(1-G144/100) -> 251100 | P144: 996.60268 | R144: =IF(H144="A","4",IF(H144="B","3",IF(H144="C","2",IF(H144="D","1",0)))) -> 2 | S144: =D144*0.4 +R144*0.3 +(1/(K144*0.3)) -> 996.62975
A145: West Midlands | B145: Flat | C145: 250000 | D145: 2230 | E145: 2024 | F145: 5.3 | G145: 7 | H145: D | I145: No | J145: First Timer | K145: =C145/D145 -> 112.10762 | L145: =PMT(F145/100/12, 300, -(C145 * (1 - G145/100))) -> 1400.1178 | M145: =-CUMIPMT(F145/1200,300,O145,1,300,0) -> 187535.33 | N145: =O145+M145 -> 420035.33 | O145: =C145*(1-G145/100) -> 232500 | P145: 892.30268 | R145: =IF(H145="A","4",IF(H145="B","3",IF(H145="C","2",IF(H145="D","1",0)))) -> 1 | S145: =D145*0.4 +R145*0.3 +(1/(K145*0.3)) -> 892.32973
A146: Yorkshire | B146: Terraced | C146: 240000 | D146: 2140 | E146: 2024 | F146: 5.5 | G146: 10 | H146: D | I146: No | J146: First Timer | K146: =C146/D146 -> 112.14953 | L146: =PMT(F146/100/12, 300, -(C146 * (1 - G146/100))) -> 1326.429 | M146: =-CUMIPMT(F146/1200,300,O146,1,300,0) -> 181928.69 | N146: =O146+M146 -> 397928.69 | O146: =C146*(1-G146/100) -> 216000 | P146: 856.30267 | R146: =IF(H146="A","4",IF(H146="B","3",IF(H146="C","2",IF(H146="D","1",0)))) -> 1 | S146: =D146*0.4 +R146*0.3 +(1/(K146*0.3)) -> 856.32972
A147: East of England | B147: Flat | C147: 276000 | D147: 2460 | E147: 2024 | F147: 5.1 | G147: 10 | H147: C | I147: No | J147: First Timer | K147: =C147/D147 -> 112.19512 | L147: =PMT(F147/100/12, 300, -(C147 * (1 - G147/100))) -> 1466.6308 | M147: =-CUMIPMT(F147/1200,300,O147,1,300,0) -> 191589.23 | N147: =O147+M147 -> 439989.23 | O147: =C147*(1-G147/100) -> 248400 | P147: 984.60267 | R147: =IF(H147="A","4",IF(H147="B","3",IF(H147="C","2",IF(H147="D","1",0)))) -> 2 | S147: =D147*0.4 +R147*0.3 +(1/(K147*0.3)) -> 984.62971
A148: North West | B148: Terraced | C148: 248000 | D148: 2210 | E148: 2024 | F148: 5.5 | G148: 8 | H148: D | I148: No | J148: First Timer | K148: =C148/D148 -> 112.21719 | L148: =PMT(F148/100/12, 300, -(C148 * (1 - G148/100))) -> 1401.102 | M148: =-CUMIPMT(F148/1200,300,O148,1,300,0) -> 192170.61 | N148: =O148+M148 -> 420330.61 | O148: =C148*(1-G148/100) -> 228160 | P148: 884.30267 | R148: =IF(H148="A","4",IF(H148="B","3",IF(H148="C","2",IF(H148="D","1",0)))) -> 1 | S148: =D148*0.4 +R148*0.3 +(1/(K148*0.3)) -> 884.3297
A149: South West | B149: Flat | C149: 255000 | D149: 2270 | E149: 2024 | F149: 5.2 | G149: 12 | H149: C | I149: No | J149: First Timer | K149: =C149/D149 -> 112.3348 | L149: =PMT(F149/100/12, 300, -(C149 * (1 - G149/100))) -> 1338.1006 | M149: =-CUMIPMT(F149/1200,300,O149,1,300,0) -> 177030.18 | N149: =O149+M149 -> 401430.18 | O149: =C149*(1-G149/100) -> 224400 | P149: 908.60267 | R149: =IF(H149="A","4",IF(H149="B","3",IF(H149="C","2",IF(H149="D","1",0)))) -> 2 | S149: =D149*0.4 +R149*0.3 +(1/(K149*0.3)) -> 908.62967
A150: East of England | B150: Flat | C150: 273000 | D150: 2430 | E150: 2024 | F150: 5.1 | G150: 10 | H150: C | I150: No | J150: First Timer | K150: =C150/D150 -> 112.34568 | L150: =PMT(F150/100/12, 300, -(C150 * (1 - G150/100))) -> 1450.6891 | M150: =-CUMIPMT(F150/1200,300,O150,1,300,0) -> 189506.74 | N150: =O150+M150 -> 435206.74 | O150: =C150*(1-G150/100) -> 245700 | P150: 972.60267 | R150: =IF(H150="A","4",IF(H150="B","3",IF(H150="C","2",IF(H150="D","1",0)))) -> 2 | S150: =D150*0.4 +R150*0.3 +(1/(K150*0.3)) -> 972.62967
A151: East of England | B151: Flat | C151: 282000 | D151: 2510 | E151: 2024 | F151: 5.2 | G151: 10 | H151: C | I151: No | J151: First Timer | K151: =C151/D151 -> 112.3506 | L151: =PMT(F151/100/12, 300, -(C151 * (1 - G151/100))) -> 1513.4133 | M151: =-CUMIPMT(F151/1200,300,O151,1,300,0) -> 200223.98 | N151: =O151+M151 -> 454023.98 | O151: =C151*(1-G151/100) -> 253800 | P151: 1004.6027 | R151: =IF(H151="A","4",IF(H151="B","3",IF(H151="C","2",IF(H151="D","1",0)))) -> 2 | S151: =D151*0.4 +R151*0.3 +(1/(K151*0.3)) -> 1004.6297
A152: East of England | B152: Flat | C152: 285000 | D152: 2530 | E152: 2023 | F152: 6 | G152: 10 | H152: C | I152: No | J152: First Timer | K152: =C152/D152 -> 112.64822 | L152: =PMT(F152/100/12, 300, -(C152 * (1 - G152/100))) -> 1652.6331 | M152: =-CUMIPMT(F152/1200,300,O152,1,300,0) -> 239289.93 | N152: =O152+M152 -> 495789.93 | O152: =C152*(1-G152/100) -> 256500 | P152: 1012.6027 | R152: =IF(H152="A","4",IF(H152="B","3",IF(H152="C","2",IF(H152="D","1",0)))) -> 2 | S152: =D152*0.4 +R152*0.3 +(1/(K152*0.3)) -> 1012.6296
A153: Yorkshire | B153: Terraced | C153: 248000 | D153: 2200 | E153: 2023 | F153: 6.5 | G153: 10 | H153: D | I153: No | J153: First Timer | K153: =C153/D153 -> 112.72727 | L153: =PMT(F153/100/12, 300, -(C153 * (1 - G153/100))) -> 1507.0624 | M153: =-CUMIPMT(F153/1200,300,O153,1,300,0) -> 228918.72 | N153: =O153+M153 -> 452118.72 | O153: =C153*(1-G153/100) -> 223200 | P153: 880.30266 | R153: =IF(H153="A","4",IF(H153="B","3",IF(H153="C","2",IF(H153="D","1",0)))) -> 1 | S153: =D153*0.4 +R153*0.3 +(1/(K153*0.3)) -> 880.32957
A154: North West | B154: Terraced | C154: 254000 | D154: 2240 | E154: 2023 | F154: 6.3 | G154: 10 | H154: D | I154: No | J154: First Timer | K154: =C154/D154 -> 113.39286 | L154: =PMT(F154/100/12, 300, -(C154 * (1 - G154/100))) -> 1515.0773 | M154: =-CUMIPMT(F154/1200,300,O154,1,300,0) -> 225923.18 | N154: =O154+M154 -> 454523.18 | O154: =C154*(1-G154/100) -> 228600 | P154: 896.30265 | R154: =IF(H154="A","4",IF(H154="B","3",IF(H154="C","2",IF(H154="D","1",0)))) -> 1 | S154: =D154*0.4 +R154*0.3 +(1/(K154*0.3)) -> 896.3294
A155: North East | B155: Terraced | C155: 250000 | D155: 2200 | E155: 2024 | F155: 5.4 | G155: 6 | H155: D | I155: No | J155: First Timer | K155: =C155/D155 -> 113.63636 | L155: =PMT(F155/100/12, 300, -(C155 * (1 - G155/100))) -> 1429.1053 | M155: =-CUMIPMT(F155/1200,300,O155,1,300,0) -> 193731.59 | N155: =O155+M155 -> 428731.59 | O155: =C155*(1-G155/100) -> 235000 | P155: 880.30264 | R155: =IF(H155="A","4",IF(H155="B","3",IF(H155="C","2",IF(H155="D","1",0)))) -> 1 | S155: =D155*0.4 +R155*0.3 +(1/(K155*0.3)) -> 880.32933
A156: East of England | B156: Flat | C156: 290000 | D156: 2550 | E156: 2024 | F156: 5.2 | G156: 10 | H156: C | I156: No | J156: First Timer | K156: =C156/D156 -> 113.72549 | L156: =PMT(F156/100/12, 300, -(C156 * (1 - G156/100))) -> 1556.347 | M156: =-CUMIPMT(F156/1200,300,O156,1,300,0) -> 205904.09 | N156: =O156+M156 -> 466904.09 | O156: =C156*(1-G156/100) -> 261000 | P156: 1020.6026 | R156: =IF(H156="A","4",IF(H156="B","3",IF(H156="C","2",IF(H156="D","1",0)))) -> 2 | S156: =D156*0.4 +R156*0.3 +(1/(K156*0.3)) -> 1020.6293
...

Sheet Average_price by region
A3: Region | B3: Average of Average_Price | E3: =(B6-B7)/B7 -> 1.729745
A4: East Midlands | B4: 326625
A5: East of England | B5: 448712.64
A6: London | B6: 653520
A7: North East | B7: 239406.98
A8: North West | B8: 298952.38
A9: South East | B9: 474319.59
A10: South West | B10: 418697.67
A11: West Midlands | B11: 361305.88
A12: Yorkshire | B12: 323627.91
A13: Grand Total | B13: 399742.18

Sheet Sales_volume
A3: Property_Type | B3: Average of Sales_Volume | C3: Sum of Average_Price
A4: Detached | B4: 1608.3333 | C4: 129502000 | E4: =C4/231 -> 560614.72
A5: Flat | B5: 2332.4885 | C5: 62637000
A6: Semi Detached | B6: 1915.7273 | C6: 62998000
A7: Terraced | B7: 1994.8387 | C7: 64257000
A8: Grand Total | B8: 1958.4606 | C8: 319394000
A23: Property_Type | B23: Average of Average_Price
A24: Detached | B24: 560614.72
A25: Flat | B25: 288649.77
A26: Semi Detached | B26: 381806.06
A27: Terraced | B27: 345467.74
A28: Grand Total | B28: 399742.18

Sheet Property_average_price by regio
A3: Average of Average_Price | B3: Year
A4: Region | B4: 2023 | C4: 2024 | D4: Grand Total | E4: Grow rate
A5: East Midlands | B5: 317478.26 | C5: 329861.54 | D5: 326625 | E5: =(C5-B5)/B5 -> 0.03900512
A6: East of England | B6: 427736.84 | C6: 454573.53 | D6: 448712.64 | E6: =(C6-B6)/B6 -> 0.062741117
A7: London | B7: 635090.91 | C7: 658717.95 | D7: 653520 | E7: =(C7-B7)/B7 -> 0.03720261
A8: North East | B8: 251344.83 | C8: 233333.33 | D8: 239406.98 | E8: =(C8-B8)/B8 -> -0.071660493
A9: North West | B9: 273173.91 | C9: 308672.13 | D9: 298952.38 | E9: =(C9-B9)/B9 -> 0.12994732
A10: South East | B10: 434130.43 | C10: 486810.81 | D10: 474319.59 | E10: =(C10-B10)/B10 -> 0.12134689
A11: South West | B11: 419000 | C11: 418623.19 | D11: 418697.67 | E11: =(C11-B11)/B11 -> -0.00089931168
A12: West Midlands | B12: 343074.07 | C12: 369793.1 | D12: 361305.88 | E12: =(C12-B12)/B12 -> 0.077881226
A13: Yorkshire | B13: 306142.86 | C13: 332068.97 | D13: 323627.91 | E13: =(C13-B13)/B13 -> 0.084686308
A14: Grand Total | B14: 369270.14 | C14: 410676.87 | D14: 399742.18
C16: =(C14-B14)/B14 -> 0.11213127 | E16: =(C7-C8)/C7 -> 0.64577657

Sheet Property_growth_rate
A3: Average of Average_Price | B3: Year
A4: Property_Type | B4: 2023 | C4: 2024 | D4: Grand Total
A5: Detached | B5: 521280.7 | C5: 573500 | D5: 560614.72
A6: Flat | B6: 270920.63 | C6: 295902.6 | D6: 288649.77
A7: Semi Detached | B7: 364378.38 | C7: 386843.75 | D7: 381806.06
A8: Terraced | B8: 326907.41 | C8: 353060.61 | D8: 345467.74
A9: Grand Total | B9: 369270.14 | C9: 410676.87 | D9: 399742.18
B12: 2023 | C12: 2024
A13: Detached | B13: 521280.7 | C13: 573500 | D13: =(C13-B13)/B13 -> 0.10017501
A14: Flat | B14: 270920.63 | C14: 295902.6 | D14: =(C14-B14)/B14 -> 0.092211368
A15: Semi Detached | B15: 364378.38 | C15: 386843.75 | D15: =(C15-B15)/B15 -> 0.061653965
A16: Terraced | B16: 326907.41 | C16: 353060.61 | D16: =(C16-B16)/B16 -> 0.080001854

Sheet Dashboard

Sheet Sheet6
A3: Region | B3: Average of Affordability_Index
A4: East Midlands | B4: 225.10602
A5: East of England | B5: 261.68975
A6: London | B6: 359.72056
A7: North East | B7: 144.30476
A8: North West | B8: 172.01107
A9: South East | B9: 277.63699
A10: South West | B10: 268.27738
A11: West Midlands | B11: 235.65145
A12: Yorkshire | B12: 241.03384
A13: Grand Total | B13: 245.51872

Sheet Mortgage_model

Sheet Sheet7
A3: Region | B3: Average of Monthly_Mortgage_cost
A4: East Midlands | B4: 1743.8925
A5: East of England | B5: 2272.3082
A6: London | B6: 3280.8675
A7: North East | B7: 1363.5604
A8: North West | B8: 1646.0601
A9: South East | B9: 2402.5528
A10: South West | B10: 2126.4191
A11: West Midlands | B11: 1901.3801
A12: Yorkshire | B12: 1728.458
A13: Grand Total | B13: 2078.7981
B17: =(B6-B7)/B7 -> 1.4061036

Sheet Sheet8
B3: Property_Type | C3: Values
B4: Detached | D4: Flat | F4: Semi Detached | H4: Terraced | J4: Total Average of Sales_Volume | K4: Total Average of Average_Price
A5: Buyer_Type | B5: Average of Sales_Volume | C5: Average of Average_Price | D5: Average of Sales_Volume | E5: Average of Average_Price | F5: Average of Sales_Volume | G5: Average of Average_Price | H5: Average of Sales_Volume | I5: Average of Average_Price
A6: First Timer | D6: 2330.787 | E6: 287879.63 | F6: 1850 | G6: 305000 | H6: 1942.4359 | I6: 296544.87 | J6: 2167.0777 | K6: 291549.6
A7: Investor | B7: 1603.8177 | C7: 574103.45 | J7: 1603.8177 | K7: 574103.45
A8: Upsizer | B8: 1641.0714 | C8: 462821.43 | D8: 2700 | E8: 455000 | F8: 1916.128 | G8: 382274.39 | H8: 2267.3333 | I8: 599866.67 | J8: 1932.3543 | K8: 421986.55
A9: Grand Total | B9: 1608.3333 | C9: 560614.72 | D9: 2332.4885 | E9: 288649.77 | F9: 1915.7273 | G9: 381806.06 | H9: 1994.8387 | I9: 345467.74 | J9: 1958.4606 | K9: 399742.18

Sheet Sheet9
A3: Count of Sales_Volume | B3: Property_Type
A4: Buyer_Type | B4: Detached | C4: Flat | D4: Semi Detached | E4: Terraced | F4: Grand Total
A5: First Timer | C5: 216 | D5: 1 | E5: 156 | F5: 373
A6: Investor | B6: 203 | F6: 203
A7: Upsizer | B7: 28 | C7: 1 | D7: 164 | E7: 30 | F7: 223
A8: Grand Total | B8: 231 | C8: 217 | D8: 165 | E8: 186 | F8: 799

Sheet Sheet13

Sheet Sheet10
A3: Average of Average_Price | B3: Property_Type
A4: Buyer_Type | B4: Detached | C4: Flat | D4: Semi Detached | E4: Terraced | F4: Grand Total
A5: First Timer | C5: 287879.63 | D5: 305000 | E5: 296544.87 | F5: 291549.6
A6: Investor | B6: 574103.45 | F6: 574103.45
A7: Upsizer | B7: 462821.43 | C7: 455000 | D7: 382274.39 | E7: 599866.67 | F7: 421986.55
A8: Grand Total | B8: 560614.72 | C8: 288649.77 | D8: 381806.06 | E8: 345467.74 | F8: 399742.18

Sheet Sheet11
G2: A | H2: =E4/E8 -> 0.0011473861
A3: Energy_Rating | B3: Average of Average_Price | C3: Average of Sales_Volume | H3: =E5/E8 -> 0.0011239753
A4: A | B4: 745852.94 | C4: 1795.4412 | E4: 1795.4412 | H4: =E6/E8 -> 0.0013266456
A5: B | B5: 475277.58 | C5: 1758.8078 | E5: 1758.8078 | H5: =E7/E8 -> 0.0013686188
A6: C | B6: 348000 | C6: 2075.9483 | E6: 2075.9483
A7: D | B7: 249481.65 | C7: 2141.6284 | E7: 2141.6284
A8: Grand Total | B8: 399742.18 | C8: 1958.4606 | E8: 1564810

Sheet Sheet12
A3: Region | B3: Average of Investment_Score
A4: East Midlands | B4: 742.4973
A5: East of England | B5: 783.63134
A6: London | B6: 886.16712
A7: North East | B7: 779.04445
A8: North West | B8: 850.79866
A9: South East | B9: 833.42824
A10: South West | B10: 711.26529
A11: West Midlands | B11: 749.19823
A12: Yorkshire | B12: 699.69713
A13: Grand Total | B13: 784.06066

Sheet Sheet14
A3: Average of Average_Price | B3: Property_Type
A4: Region | B4: Detached | C4: Flat | D4: Semi Detached | E4: Terraced | F4: Grand Total
A5: East Midlands | B5: 439500 | C5: 255812.5 | D5: 367954.55 | E5: 301666.67 | F5: 326625
A6: East of England | B6: 568972.22 | C6: 300000 | D6: 432388.89 | E6: 362285.71 | F6: 448712.64
A7: London | B7: 853513.51 | C7: 478060.61 | E7: 599866.67 | F7: 653520
A8: North East | B8: 350714.29 | C8: 201222.22 | D8: 285916.67 | E8: 240612.9 | F8: 239406.98
A9: North West | B9: 407142.86 | C9: 226666.67 | D9: 332633.33 | E9: 282862.07 | F9: 298952.38
A10: South East | B10: 622593.75 | C10: 329461.54 | D10: 463062.5 | E10: 386000 | F10: 474319.59
A11: South West | B11: 515419.35 | C11: 284285.71 | D11: 401464.29 | E11: 339950 | F11: 418697.67
A12: West Midlands | B12: 485531.25 | C12: 258166.67 | D12: 356142.86 | E12: 308500 | F12: 361305.88
A13: Yorkshire | B13: 414060.61 | C13: 209375 | D13: 322375 | E13: 269523.81 | F13: 323627.91
A14: Grand Total | B14: 560614.72 | C14: 288649.77 | D14: 381806.06 | E14: 345467.74 | F14: 399742.18

Sheet Sheet15
A3: Year | B3: Region | C3: Average of Average_Price
A4: 2023 | B4: East Midlands | C4: 317478.26
B5: East of England | C5: 427736.84
B6: London | C6: 635090.91
B7: North East | C7: 251344.83
B8: North West | C8: 273173.91
B9: South East | C9: 434130.43
B10: South West | C10: 419000
B11: West Midlands | C11: 343074.07
B12: Yorkshire | C12: 306142.86
A13: 2023 Total | C13: 369270.14
A14: 2024 | B14: East Midlands | C14: 329861.54
B15: East of England | C15: 454573.53
B16: London | C16: 658717.95
B17: North East | C17: 233333.33
B18: North West | C18: 308672.13
B19: South East | C19: 486810.81
B20: South West | C20: 418623.19
B21: West Midlands | C21: 369793.1
B22: Yorkshire | C22: 332068.97
A23: 2024 Total | C23: 410676.87
A24: Grand Total | C24: 399742.18

Sheet Sheet16
A3: Region | B3: Average of Sales_Volume
A4: East Midlands | B4: 1854.7727
A5: East of England | B5: 1957.1264
A6: London | B6: 2213.15
A7: North East | B7: 1946.6279
A8: North West | B8: 2125.8929
A9: South East | B9: 2081.3402
A10: South West | B10: 1776.1628
A11: West Midlands | B11: 1871.4118
A12: Yorkshire | B12: 1747.7907
A13: Grand Total | B13: 1958.4606

Sheet Sheet17
A3: Region | B3: Average of Investment_Score_1
A4: East Midlands | B4: 742.51591
A5: East of England | B5: 783.64606
A6: London | B6: 886.17843
A7: North East | B7: 779.07067
A8: North West | B8: 850.8212
A9: South East | B9: 833.44275
A10: South West | B10: 711.27885
A11: West Midlands | B11: 749.21601
A12: Yorkshire | B12: 699.71511
A13: (blank)
A14: Grand Total | B14: 784.07797

Sheet Sheet4
E1: =(C4+D4)/2 -> 371379.21
C3: 2023 | D3: 2024
B4: Detached | C4: =AVERAGE(Copy!C2:C528) -> 341779.89 | D4: =AVERAGE(Copy!C7:C798) -> 400978.54 | E4: =(D4-C4)/C4 -> 0.17320694
B5: Semi Detached | C5: =AVERAGE(Copy!C31:C532) -> 350350.6 | D5: =AVERAGE(Copy!C5:C800) -> 400507.54 | E5: =(D5-C5)/C5 -> 0.14316214
B6: Flat | C6: =AVERAGE(Copy!C6:C533) -> 343164.77 | D6: =AVERAGE(Copy!C3:C795) -> 399576.29 | E6: =(D6-C6)/C6 -> 0.1643861
B7: Terraced | C7: =AVERAGE(Copy!C4:C521) -> 341067.57 | D7: =AVERAGE(Copy!C14:C799) -> 402478.37 | E7: =(D7-C7)/C7 -> 0.18005466
B10: East Midlands East of England London North East North West South East South West West Midlands Yorkshire
C11: 2023 | D11: 2024
B12: East Midlands | C12: =AVERAGE(Copy!C6:C511) -> 339418.97
B13: East of England | C13: =AVERAGE(Copy!C10:C533) -> 344095.42
B14: London | C14: =AVERAGE(Copy!C2:C525) -> 341188.93
B15: North East | C15: =AVERAGE(Copy!C18:C532) -> 346363.11
B16: North West
B17: South East
B18: South West
B19: West Midlands
B20: Yorkshire
