Workbook

Sheet Patients 
A1: PatientID | B1: Age | C1: Gender | D1: Ethnicity | E1: Postcode | F1: LongTermCondition
A2: 1 | B2: 54 | C2: Male | D2: White British | E2: SL1 | F2: Yes
A3: 2 | B3: 33 | C3: Female | D3: Black African | E3: EN3 | F3: No
A4: 3 | B4: 72 | C4: Female | D4: White British | E4: UB2 | F4: Yes
A5: 4 | B5: 41 | C5: Male | D5: Indian | E5: SL3 | F5: No
A6: 5 | B6: 65 | C6: Male | D6: Pakistani | E6: RG1 | F6: Yes
A7: 6 | B7: 29 | C7: Female | D7: White Other | E7: HP1 | F7: No
A8: 7 | B8: 58 | C8: Male | D8: Black Caribbean | E8: SL2 | F8: Yes
A9: 8 | B9: 47 | C9: Female | D9: Bangladeshi | E9: UB3 | F9: No
A10: 9 | B10: 36 | C10: Male | D10: White British | E10: SL1 | F10: No
A11: 10 | B11: 82 | C11: Female | D11: Chinese | E11: RG2 | F11: Yes
A12: 11 | B12: 23 | C12: Male | D12: White British | E12: HP2 | F12: No
A13: 12 | B13: 51 | C13: Female | D13: Indian | E13: SL4 | F13: Yes
... A1001: 1000 | B1001: 79 | C1001: Male | D1001: White British | E1001: SL4 | F1001: Yes

Sheet Average_waitingTime_by_deprtmt
A3: DepartmentID | B3: Average of WaitingTimeMinutes
A4: A&E (Emergency) | B4: 99.169231
A5: Cardiology | B5: 49.639344
A6: ENT | B6: 102.90476
A7: Gastroenterology | B7: 31.015873
A8: General Surgery | B8: 36.737705
A9: Geriatrics | B9: 43.47619
A10: Maternity | B10: 107.53125
A11: Neurology | B11: 32.3125
A12: Oncology | B12: 32.065574
A13: Orthopaedics | B13: 36.40625
A14: Paediatrics | B14: 114
A15: Renal Medicine | B15: 33.453125
... A17: Grand Total | B17: 63.550796

Sheet Admission_type_by_Outcome
A3: Count of AdmissionID | B3: AdmissionType
A4: Outcome | B4: Elective | C4: Emergency | D4: Transfer | E4: Grand Total
A5: Deceased | C5: 1 | E5: 1
A6: Discharged | B6: 411 | C6: 288 | D6: 47 | E6: 746
A7: Transferred | B7: 30 | C7: 26 | D7: 14 | E7: 70
A8: Grand Total | B8: 441 | C8: 315 | D8: 61 | E8: 817

Sheet AWT_by_staff_on_duty
A3: StaffOnDuty | B3: Average of WaitingTimeMinutes
A4: 7 | B4: 28
A5: 8 | B5: 119
A6: 9 | B6: 27
A7: 10 | B7: 95.75
A8: 11 | B8: 54.333333
A9: 12 | B9: 25.166667
A10: 13 | B10: 101.66667
A11: 14 | B11: 73
A12: 15 | B12: 106
A13: 16 | B13: 21.4
A14: 17 | B14: 18.5
A15: 18 | B15: 44
... A21: 24 | B21: 103.5
A22: (blank) | B22: 63.720207
A23: Grand Total | B23: 63.550796

Sheet Bed_availability
A3: DepartmentID | B3: Average of WaitingTimeMinutes | C3: Average of BedAvailable
A4: A&E (Emergency) | B4: 99.169231 | C4: 42
A5: Cardiology | B5: 49.639344 | C5: 38
A6: ENT | B6: 102.90476 | C6: 20
A7: Gastroenterology | B7: 31.015873 | C7: 29
A8: General Surgery | B8: 36.737705 | C8: 44
A9: Geriatrics | B9: 43.47619 | C9: 46
A10: Maternity | B10: 107.53125 | C10: 34
A11: Neurology | B11: 32.3125 | C11: 32
A12: Oncology | B12: 32.065574 | C12: 28
A13: Orthopaedics | B13: 36.40625 | C13: 40
A14: Paediatrics | B14: 114 | C14: 30
A15: Renal Medicine | B15: 33.453125 | C15: 26
... A17: Grand Total | B17: 63.550796 | C17: 34.221542

Sheet Admissions
A1: AdmissionID | B1: PatientID | C1: DepartmentID | D1: AdmissionDate | E1: DischargeDate | F1: AdmissionType | G1: LengthOfStay | H1: WaitingTimeMinutes | I1: Outcome | J1: BedPressureScore | K1: Lookupkey | L1: StaffOnDuty | M1: BedAvailable
A2: 1 | B2: 482 | C2: A&E (Emergency) | D2: 45660 | F2: Emergency | G2: 2 | H2: 122 | I2: Discharged | J2: =G2*(H2/30) -> 8.1333333 | K2: =TEXT(D2, "dd/mm/yyyy")&C2 -> 03/01/2025A&E (Emergency) | L2: =VLOOKUP(K2, Sheet2!$A$2:$B$4186, 2,FALSE) -> 22 | M2: =VLOOKUP(C2,Depts!$B$1:$D$16,3,FALSE) -> 42
A3: 2 | B3: 119 | C3: General Surgery | D3: 45661 | E3: 45666 | F3: Elective | G3: 5 | H3: 14 | I3: Discharged | J3: =G3*(H3/30) -> 2.3333333 | K3: =TEXT(D3, "dd/mm/yyyy")&C3 -> 04/01/2025General Surgery | L3: =VLOOKUP(K3, Sheet2!$A$2:$B$4186, 2,FALSE) -> 15 | M3: =VLOOKUP(C3,Depts!$B$1:$D$16,3,FALSE) -> 44
A4: 3 | B4: 877 | C4: Oncology | D4: 45662 | E4: 45669 | F4: Elective | G4: 7 | H4: 20 | I4: Discharged | J4: =G4*(H4/30) -> 4.6666667 | K4: =TEXT(D4, "dd/mm/yyyy")&C4 -> 05/01/2025Oncology | L4: =VLOOKUP(K4, Sheet2!$A$2:$B$4186, 2,FALSE) -> 12 | M4: =VLOOKUP(C4,Depts!$B$1:$D$16,3,FALSE) -> 28
A5: 4 | B5: 54 | C5: Respiratory | D5: 45663 | E5: 45665 | F5: Emergency | G5: 2 | H5: 230 | I5: Discharged | J5: =G5*(H5/30) -> 15.333333 | K5: =TEXT(D5, "dd/mm/yyyy")&C5 -> 06/01/2025Respiratory | L5: =VLOOKUP(K5, Sheet2!$A$2:$B$4186, 2,FALSE) -> 15 | M5: =VLOOKUP(C5,Depts!$B$1:$D$16,3,FALSE) -> 36
A6: 5 | B6: 691 | C6: Renal Medicine | D6: 45663 | E6: 45668 | F6: Elective | G6: 5 | H6: 10 | I6: Transferred | J6: =G6*(H6/30) -> 1.6666667 | K6: =TEXT(D6, "dd/mm/yyyy")&C6 -> 06/01/2025Renal Medicine | L6: =VLOOKUP(K6, Sheet2!$A$2:$B$4186, 2,FALSE) -> 21 | M6: =VLOOKUP(C6,Depts!$B$1:$D$16,3,FALSE) -> 26
A7: 6 | B7: 305 | C7: Cardiology | D7: 45664 | E7: 45667 | F7: Transfer | G7: 3 | H7: 35 | I7: Discharged | J7: =G7*(H7/30) -> 3.5 | K7: =TEXT(D7, "dd/mm/yyyy")&C7 -> 07/01/2025Cardiology | L7: =VLOOKUP(K7, Sheet2!$A$2:$B$4186, 2,FALSE) -> 17 | M7: =VLOOKUP(C7,Depts!$B$1:$D$16,3,FALSE) -> 38
A8: 7 | B8: 812 | C8: Neurology | D8: 45665 | E8: 45671 | F8: Elective | G8: 6 | H8: 2 | I8: Discharged | J8: =G8*(H8/30) -> 0.4 | K8: =TEXT(D8, "dd/mm/yyyy")&C8 -> 08/01/2025Neurology | L8: =VLOOKUP(K8, Sheet2!$A$2:$B$4186, 2,FALSE) -> 12 | M8: =VLOOKUP(C8,Depts!$B$1:$D$16,3,FALSE) -> 32
A9: 8 | B9: 147 | C9: A&E (Emergency) | D9: 45665 | E9: 45666 | F9: Emergency | G9: 1 | H9: 21 | I9: Discharged | J9: =G9*(H9/30) -> 0.7 | K9: =TEXT(D9, "dd/mm/yyyy")&C9 -> 08/01/2025A&E (Emergency) | L9: =VLOOKUP(K9, Sheet2!$A$2:$B$4186, 2,FALSE) -> 24 | M9: =VLOOKUP(C9,Depts!$B$1:$D$16,3,FALSE) -> 42
A10: 9 | B10: 529 | C10: Maternity | D10: 45666 | E10: 45670 | F10: Elective | G10: 4 | H10: 29 | I10: Discharged | J10: =G10*(H10/30) -> 3.8666667 | K10: =TEXT(D10, "dd/mm/yyyy")&C10 -> 09/01/2025Maternity | L10: =VLOOKUP(K10, Sheet2!$A$2:$B$4186, 2,FALSE) -> 12 | M10: =VLOOKUP(C10,Depts!$B$1:$D$16,3,FALSE) -> 34
A11: 10 | B11: 63 | C11: Orthopaedics | D11: 45667 | E11: 45672 | F11: Elective | G11: 5 | H11: 20 | I11: Discharged | J11: =G11*(H11/30) -> 3.3333333 | K11: =TEXT(D11, "dd/mm/yyyy")&C11 -> 10/01/2025Orthopaedics | L11: =VLOOKUP(K11, Sheet2!$A$2:$B$4186, 2,FALSE) -> 13 | M11: =VLOOKUP(C11,Depts!$B$1:$D$16,3,FALSE) -> 40
A12: 11 | B12: 914 | C12: Paediatrics | D12: 45667 | E12: 45669 | F12: Emergency | G12: 2 | H12: 77 | I12: Discharged | J12: =G12*(H12/30) -> 5.1333333 | K12: =TEXT(D12, "dd/mm/yyyy")&C12 -> 10/01/2025Paediatrics | L12: =VLOOKUP(K12, Sheet2!$A$2:$B$4186, 2,FALSE) -> 10 | M12: =VLOOKUP(C12,Depts!$B$1:$D$16,3,FALSE) -> 30
A13: 12 | B13: 372 | C13: Gastroenterology | D13: 45668 | E13: 45673 | F13: Elective | G13: 5 | H13: 43 | I13: Discharged | J13: =G13*(H13/30) -> 7.1666667 | K13: =TEXT(D13, "dd/mm/yyyy")&C13 -> 11/01/2025Gastroenterology | L13: =VLOOKUP(K13, Sheet2!$A$2:$B$4186, 2,FALSE) -> 7 | M13: =VLOOKUP(C13,Depts!$B$1:$D$16,3,FALSE) -> 29
A14: 13 | B14: 250 | C14: ENT | D14: 45669 | E14: 45671 | F14: Emergency | G14: 2 | H14: 238 | I14: Discharged | J14: =G14*(H14/30) -> 15.866667 | K14: =TEXT(D14, "dd/mm/yyyy")&C14 -> 12/01/2025ENT | L14: =VLOOKUP(K14, Sheet2!$A$2:$B$4186, 2,FALSE) -> 10 | M14: =VLOOKUP(C14,Depts!$B$1:$D$16,3,FALSE) -> 20
... A47: 46 | B47: 675 | C47: Renal Medicine | D47: 45689 | E47: 45694 | F47: Elective | G47: 5 | H47: 23 | I47: Discharged | J47: =G47*(H47/30) -> 3.8333333 | K47: =TEXT(D47, "dd/mm/yyyy")&C47 -> 01/02/2025Renal Medicine | L47: =VLOOKUP(K47, Sheet2!$A$2:$B$4186, 2,FALSE) -> 17 | M47: =VLOOKUP(C47,Depts!$B$1:$D$16,3,FALSE) -> 26
A48: 47 | B48: 56 | C48: Neurology | D48: 45690 | E48: 45696 | F48: Elective | G48: 6 | H48: 28 | I48: Discharged | J48: =G48*(H48/30) -> 5.6 | K48: =TEXT(D48, "dd/mm/yyyy")&C48 -> 02/02/2025Neurology | L48: =VLOOKUP(K48, Sheet2!$A$2:$B$4186, 2,FALSE) -> 9 | M48: =VLOOKUP(C48,Depts!$B$1:$D$16,3,FALSE) -> 32 | N48: =ISNUMBER(D48) -> TRUE
A49: 48 | B49: 779 | C49: Maternity | D49: 45690 | E49: 45692 | F49: Emergency | G49: 2 | H49: 143 | I49: Discharged | J49: =G49*(H49/30) -> 9.5333333 | K49: =TEXT(D49, "dd/mm/yyyy")&C49 -> 02/02/2025Maternity | L49: =VLOOKUP(K49, Sheet2!$A$2:$B$4186, 2,FALSE) -> 9 | M49: =VLOOKUP(C49,Depts!$B$1:$D$16,3,FALSE) -> 34 | N49: =ISNUMBER(D49) -> TRUE
A50: 49 | B50: 602 | C50: Orthopaedics | D50: 45691 | E50: 45696 | F50: Elective | G50: 5 | H50: 1 | I50: Discharged | J50: =G50*(H50/30) -> 0.16666667 | K50: =TEXT(D50, "dd/mm/yyyy")&C50 -> 03/02/2025Orthopaedics | L50: =VLOOKUP(K50, Sheet2!$A$2:$B$4186, 2,FALSE) -> 16 | M50: =VLOOKUP(C50,Depts!$B$1:$D$16,3,FALSE) -> 40 | N50: =ISNUMBER(D50) -> TRUE
A51: 50 | B51: 919 | C51: Paediatrics | D51: 45691 | E51: 45693 | F51: Emergency | G51: 2 | H51: 187 | I51: Discharged | J51: =G51*(H51/30) -> 12.466667 | K51: =TEXT(D51, "dd/mm/yyyy")&C51 -> 03/02/2025Paediatrics | L51: =VLOOKUP(K51, Sheet2!$A$2:$B$4186, 2,FALSE) -> 13 | M51: =VLOOKUP(C51,Depts!$B$1:$D$16,3,FALSE) -> 30 | N51: =ISNUMBER(D51) -> TRUE
A52: 51 | B52: 964 | C52: Gastroenterology | D52: 45692 | E52: 45697 | F52: Elective | G52: 5 | H52: 4 | I52: Discharged | J52: =G52*(H52/30) -> 0.66666667 | K52: =TEXT(D52, "dd/mm/yyyy")&C52 -> 04/02/2025Gastroenterology | L52: =VLOOKUP(K52, Sheet2!$A$2:$B$4186, 2,FALSE) -> 11 | M52: =VLOOKUP(C52,Depts!$B$1:$D$16,3,FALSE) -> 29 | N52: =ISNUMBER(D52) -> TRUE
A53: 52 | B53: 569 | C53: ENT | D53: 45693 | E53: 45695 | F53: Emergency | G53: 2 | H53: 131 | I53: Discharged | J53: =G53*(H53/30) -> 8.7333333 | K53: =TEXT(D53, "dd/mm/yyyy")&C53 -> 05/02/2025ENT | L53: =VLOOKUP(K53, Sheet2!$A$2:$B$4186, 2,FALSE) -> 12 | M53: =VLOOKUP(C53,Depts!$B$1:$D$16,3,FALSE) -> 20 | N53: =ISNUMBER(D53) -> TRUE
A54: 53 | B54: 191 | C54: Geriatrics | D54: 45693 | E54: 45699 | F54: Elective | G54: 6 | H54: 27 | I54: Discharged | J54: =G54*(H54/30) -> 5.4 | K54: =TEXT(D54, "dd/mm/yyyy")&C54 -> 05/02/2025Geriatrics | L54: =VLOOKUP(K54, Sheet2!$A$2:$B$4186, 2,FALSE) -> 14 | M54: =VLOOKUP(C54,Depts!$B$1:$D$16,3,FALSE) -> 46 | N54: =ISNUMBER(D54) -> TRUE
A55: 54 | B55: 166 | C55: Respiratory | D55: 45694 | E55: 45696 | F55: Emergency | G55: 2 | H55: 111 | I55: Discharged | J55: =G55*(H55/30) -> 7.4 | K55: =TEXT(D55, "dd/mm/yyyy")&C55 -> 06/02/2025Respiratory | L55: =VLOOKUP(K55, Sheet2!$A$2:$B$4186, 2,FALSE) -> 13 | M55: =VLOOKUP(C55,Depts!$B$1:$D$16,3,FALSE) -> 36 | N55: =ISNUMBER(D55) -> TRUE
A56: 55 | B56: 873 | C56: General Surgery | D56: 45695 | E56: 45700 | F56: Elective | G56: 5 | H56: 19 | I56: Discharged | J56: =G56*(H56/30) -> 3.1666667 | K56: =TEXT(D56, "dd/mm/yyyy")&C56 -> 07/02/2025General Surgery | L56: =VLOOKUP(K56, Sheet2!$A$2:$B$4186, 2,FALSE) -> 18 | M56: =VLOOKUP(C56,Depts!$B$1:$D$16,3,FALSE) -> 44 | N56: =ISNUMBER(D56) -> TRUE
A57: 56 | B57: 926 | C57: Cardiology | D57: 45695 | E57: 45698 | F57: Transfer | G57: 3 | H57: 40 | I57: Discharged | J57: =G57*(H57/30) -> 4 | K57: =TEXT(D57, "dd/mm/yyyy")&C57 -> 07/02/2025Cardiology | L57: =VLOOKUP(K57, Sheet2!$A$2:$B$4186, 2,FALSE) -> 15 | M57: =VLOOKUP(C57,Depts!$B$1:$D$16,3,FALSE) -> 38 | N57: =ISNUMBER(D57) -> TRUE
A58: 57 | B58: 329 | C58: Oncology | D58: 45696 | E58: 45701 | F58: Elective | G58: 5 | H58: 11 | I58: Discharged | J58: =G58*(H58/30) -> 1.8333333 | K58: =TEXT(D58, "dd/mm/yyyy")&C58 -> 08/02/2025Oncology | L58: =VLOOKUP(K58, Sheet2!$A$2:$B$4186, 2,FALSE) -> 13 | M58: =VLOOKUP(C58,Depts!$B$1:$D$16,3,FALSE) -> 28 | N58: =ISNUMBER(D58) -> TRUE
A59: 58 | B59: 401 | C59: A&E (Emergency) | D59: 45696 | E59: 45697 | F59: Emergency | G59: 1 | H59: 192 | I59: Discharged | J59: =G59*(H59/30) -> 6.4 | K59: =TEXT(D59, "dd/mm/yyyy")&C59 -> 08/02/2025A&E (Emergency) | L59: =VLOOKUP(K59, Sheet2!$A$2:$B$4186, 2,FALSE) -> 20 | M59: =VLOOKUP(C59,Depts!$B$1:$D$16,3,FALSE) -> 42 | N59: =ISNUMBER(D59) -> TRUE
... A507: 628 | B507: 881 | C507: Renal Medicine | D507: 45985 | E507: 45990 | F507: Elective | G507: 5 | H507: 44 | I507: Discharged | J507: =G507*(H507/30) -> 7.3333333 | K507: =TEXT(D507, "dd/mm/yyyy")&C507 -> 24/11/2025Renal Medicine | L507: =VLOOKUP(K507, Sheet2!$A$2:$B$4186, 2,FALSE) -> #N/A | M507: =VLOOKUP(C507,Depts!$B$1:$D$16,3,FALSE) -> 26 | N507: =ISNUMBER(D507) -> TRUE
A508: 629 | B508: 102 | C508: Neurology | D508: 45986 | E508: 31/11/2025 | F508: Elective | G508: 6 | H508: 31 | I508: Discharged | J508: =G508*(H508/30) -> 6.2 | K508: =TEXT(D508, "dd/mm/yyyy")&C508 -> 25/11/2025Neurology | L508: =VLOOKUP(K508, Sheet2!$A$2:$B$4186, 2,FALSE) -> #N/A | M508: =VLOOKUP(C508,Depts!$B$1:$D$16,3,FALSE) -> 32 | N508: =ISNUMBER(D508) -> TRUE
A509: 630 | B509: 342 | C509: Maternity | D509: 45986 | E509: 45988 | F509: Emergency | G509: 2 | H509: 192 | I509: Discharged | J509: =G509*(H509/30) -> 12.8 | K509: =TEXT(D509, "dd/mm/yyyy")&C509 -> 25/11/2025Maternity | L509: =VLOOKUP(K509, Sheet2!$A$2:$B$4186, 2,FALSE) -> #N/A | M509: =VLOOKUP(C509,Depts!$B$1:$D$16,3,FALSE) -> 34 | N509: =ISNUMBER(D509) -> TRUE
A510: 631 | B510: 189 | C510: Orthopaedics | D510: 45987 | E510: 31/11/2025 | F510: Elective | G510: 5 | H510: 41 | I510: Discharged | J510: =G510*(H510/30) -> 6.8333333 | K510: =TEXT(D510, "dd/mm/yyyy")&C510 -> 26/11/2025Orthopaedics | L510: =VLOOKUP(K510, Sheet2!$A$2:$B$4186, 2,FALSE) -> #N/A | M510: =VLOOKUP(C510,Depts!$B$1:$D$16,3,FALSE) -> 40 | N510: =ISNUMBER(D510) -> TRUE
A511: 632 | B511: 836 | C511: Paediatrics | D511: 45987 | E511: 45989 | F511: Emergency | G511: 2 | H511: 238 | I511: Discharged | J511: =G511*(H511/30) -> 15.866667 | K511: =TEXT(D511, "dd/mm/yyyy")&C511 -> 26/11/2025Paediatrics | L511: =VLOOKUP(K511, Sheet2!$A$2:$B$4186, 2,FALSE) -> #N/A | M511: =VLOOKUP(C511,Depts!$B$1:$D$16,3,FALSE) -> 30 | N511: =ISNUMBER(D511) -> TRUE
A512: 633 | B512: 14 | C512: Gastroenterology | D512: 45988 | E512: 45992 | F512: Elective | G512: 5 | H512: 12 | I512: Discharged | J512: =G512*(H512/30) -> 2 | K512: =TEXT(D512, "dd/mm/yyyy")&C512 -> 27/11/2025Gastroenterology | L512: =VLOOKUP(K512, Sheet2!$A$2:$B$4186, 2,FALSE) -> #N/A | M512: =VLOOKUP(C512,Depts!$B$1:$D$16,3,FALSE) -> 29 | N512: =ISNUMBER(D512) -> TRUE
A513: 634 | B513: 449 | C513: ENT | D513: 45989 | E513: 45991 | F513: Emergency | G513: 2 | H513: 120 | I513: Discharged | J513: =G513*(H513/30) -> 8 | K513: =TEXT(D513, "dd/mm/yyyy")&C513 -> 28/11/2025ENT | L513: =VLOOKUP(K513, Sheet2!$A$2:$B$4186, 2,FALSE) -> #N/A | M513: =VLOOKUP(C513,Depts!$B$1:$D$16,3,FALSE) -> 20 | N513: =ISNUMBER(D513) -> TRUE
A514: 635 | B514: 93 | C514: Geriatrics | D514: 45989 | E514: 45994 | F514: Elective | G514: 6 | H514: 32 | I514: Discharged | J514: =G514*(H514/30) -> 6.4 | K514: =TEXT(D514, "dd/mm/yyyy")&C514 -> 28/11/2025Geriatrics | L514: =VLOOKUP(K514, Sheet2!$A$2:$B$4186, 2,FALSE) -> #N/A | M514: =VLOOKUP(C514,Depts!$B$1:$D$16,3,FALSE) -> 46 | N514: =ISNUMBER(D514) -> TRUE
A515: 636 | B515: 738 | C515: Respiratory | D515: 45990 | E515: 31/11/2025 | F515: Emergency | G515: 2 | H515: 111 | I515: Discharged | J515: =G515*(H515/30) -> 7.4 | K515: =TEXT(D515, "dd/mm/yyyy")&C515 -> 29/11/2025Respiratory | L515: =VLOOKUP(K515, Sheet2!$A$2:$B$4186, 2,FALSE) -> #N/A | M515: =VLOOKUP(C515,Depts!$B$1:$D$16,3,FALSE) -> 36 | N515: =ISNUMBER(D515) -> TRUE
A516: 637 | B516: 390 | C516: General Surgery | D516: 45991 | E516: 45995 | F516: Elective | G516: 5 | H516: 25 | I516: Discharged | J516: =G516*(H516/30) -> 4.1666667 | K516: =TEXT(D516, "dd/mm/yyyy")&C516 -> 30/11/2025General Surgery | L516: =VLOOKUP(K516, Sheet2!$A$2:$B$4186, 2,FALSE) -> #N/A | M516: =VLOOKUP(C516,Depts!$B$1:$D$16,3,FALSE) -> 44 | N516: =ISNUMBER(D516) -> TRUE
A517: 638 | B517: 582 | C517: Cardiology | D517: 45991 | E517: 45993 | F517: Transfer | G517: 3 | H517: 17 | I517: Transferred | J517: =G517*(H517/30) -> 1.7 | K517: =TEXT(D517, "dd/mm/yyyy")&C517 -> 30/11/2025Cardiology | L517: =VLOOKUP(K517, Sheet2!$A$2:$B$4186, 2,FALSE) -> #N/A | M517: =VLOOKUP(C517,Depts!$B$1:$D$16,3,FALSE) -> 38 | N517: =ISNUMBER(D517) -> TRUE
A518: 639 | B518: 944 | C518: Oncology | D518: 31/11/2025 | E518: 45996 | F518: Elective | G518: 5 | H518: 42 | I518: Discharged | J518: =G518*(H518/30) -> 7 | K518: =TEXT(D518, "dd/mm/yyyy")&C518 -> 31/11/2025Oncology | L518: =VLOOKUP(K518, Sheet2!$A$2:$B$4186, 2,FALSE) -> #N/A | M518: =VLOOKUP(C518,Depts!$B$1:$D$16,3,FALSE) -> 28 | N518: =ISNUMBER(D518) -> FALSE
A519: 640 | B519: 659 | C519: A&E (Emergency) | D519: 31/11/2025 | E519: 45992 | F519: Emergency | G519: 1 | H519: 21 | I519: Discharged | J519: =G519*(H519/30) -> 0.7 | K519: =TEXT(D519, "dd/mm/yyyy")&C519 -> 31/11/2025A&E (Emergency) | L519: =VLOOKUP(K519, Sheet2!$A$2:$B$4186, 2,FALSE) -> #N/A | M519: =VLOOKUP(C519,Depts!$B$1:$D$16,3,FALSE) -> 42 | N519: =ISNUMBER(D519) -> FALSE
...

Sheet Depts
A1: DepartmentID | B1: DepartmentName | C1: Ward | D1: BedsAvailable | E1: Region | L1: DepartmentName | N1: BedsAvailable
A2: 1 | B2: A&E (Emergency) | C2: Emergency Ward | D2: 42 | E2: London | L2: A&E (Emergency) | N2: 42
A3: 2 | B3: Cardiology | C3: Heart Ward | D3: 38 | E3: South East | L3: Cardiology | N3: 38
A4: 3 | B4: Respiratory | C4: Respiratory Ward | D4: 36 | E4: Midlands | L4: Respiratory | N4: 36
A5: 4 | B5: General Surgery | C5: Surgery Ward 1 | D5: 44 | E5: North West | L5: General Surgery | N5: 44
A6: 5 | B6: Orthopaedics | C6: Ortho Ward | D6: 40 | E6: East of England | L6: Orthopaedics | N6: 40
A7: 6 | B7: Neurology | C7: Neuro Ward | D7: 32 | E7: London | L7: Neurology | N7: 32
A8: 7 | B8: Oncology | C8: Cancer Care Ward | D8: 28 | E8: South West | L8: Oncology | N8: 28
A9: 8 | B9: Paediatrics | C9: Children's Ward | D9: 30 | E9: North East & Yorkshire | L9: Paediatrics | N9: 30
A10: 9 | B10: Maternity | C10: Maternity Ward | D10: 34 | E10: South East | L10: Maternity | N10: 34
A11: 10 | B11: Renal Medicine | C11: Renal Ward | D11: 26 | E11: Midlands | L11: Renal Medicine | N11: 26
A12: 11 | B12: Gastroenterology | C12: GI Ward | D12: 29 | E12: North West | L12: Gastroenterology | N12: 29
A13: 12 | B13: Endocrinology | C13: Endocrine Ward | D13: 22 | E13: East of England | L13: Endocrinology | N13: 22
... A16: 15 | B16: Geriatrics | C16: Elderly Care Ward | D16: 46 | E16: London | L16: Geriatrics | N16: 46

Sheet StaffingLevels
A1: Date | B1: DepartmentID | C1: StaffOnDuty | D1: Lookupkey
A2: 45658 | B2: A&E (Emergency) | C2: 24 | D2: =TEXT(A2, "dd/mm/yyyy")&B2 -> 01/01/2025A&E (Emergency)
A3: 45658 | B3: Cardiology | C3: 16 | D3: =TEXT(A3, "dd/mm/yyyy")&B3 -> 01/01/2025Cardiology
A4: 45658 | B4: Respiratory | C4: 12 | D4: =TEXT(A4, "dd/mm/yyyy")&B4 -> 01/01/2025Respiratory
A5: 45658 | B5: General Surgery | C5: 19 | D5: =TEXT(A5, "dd/mm/yyyy")&B5 -> 01/01/2025General Surgery
A6: 45658 | B6: Orthopaedics | C6: 14 | D6: =TEXT(A6, "dd/mm/yyyy")&B6 -> 01/01/2025Orthopaedics
A7: 45658 | B7: Neurology | C7: 12 | D7: =TEXT(A7, "dd/mm/yyyy")&B7 -> 01/01/2025Neurology
A8: 45658 | B8: Oncology | C8: 17 | D8: =TEXT(A8, "dd/mm/yyyy")&B8 -> 01/01/2025Oncology
A9: 45658 | B9: Paediatrics | C9: 11 | D9: =TEXT(A9, "dd/mm/yyyy")&B9 -> 01/01/2025Paediatrics
A10: 45658 | B10: Maternity | C10: 12 | D10: =TEXT(A10, "dd/mm/yyyy")&B10 -> 01/01/2025Maternity
A11: 45658 | B11: Renal Medicine | C11: 20 | D11: =TEXT(A11, "dd/mm/yyyy")&B11 -> 01/01/2025Renal Medicine
A12: 45658 | B12: Gastroenterology | C12: 10 | D12: =TEXT(A12, "dd/mm/yyyy")&B12 -> 01/01/2025Gastroenterology
A13: 45658 | B13: Endocrinology | C13: 8 | D13: =TEXT(A13, "dd/mm/yyyy")&B13 -> 01/01/2025Endocrinology
... A4186: 45922 | B4186: Geriatrics | C4186: 16 | D4186: =TEXT(A4186, "dd/mm/yyyy")&B4186 -> 22/09/2025Geriatrics

Sheet Sheet2
A1: Lookupkey | B1: StaffOnDuty
A2: 01/01/2025A&E (Emergency) | B2: 24
A3: 01/01/2025Cardiology | B3: 16
A4: 01/01/2025Respiratory | B4: 12
A5: 01/01/2025General Surgery | B5: 19
A6: 01/01/2025Orthopaedics | B6: 14
A7: 01/01/2025Neurology | B7: 12
A8: 01/01/2025Oncology | B8: 17
A9: 01/01/2025Paediatrics | B9: 11
A10: 01/01/2025Maternity | B10: 12
A11: 01/01/2025Renal Medicine | B11: 20
A12: 01/01/2025Gastroenterology | B12: 10
A13: 01/01/2025Endocrinology | B13: 8
... A4186: 22/09/2025Geriatrics | B4186: 16
